[2020-04-07 22:47:55,165] {taskinstance.py:655} INFO - Dependencies all met for <TaskInstance: atp_data07.create_tbl_sample 2020-04-07T00:00:00+00:00 [queued]>
[2020-04-07 22:47:55,174] {taskinstance.py:655} INFO - Dependencies all met for <TaskInstance: atp_data07.create_tbl_sample 2020-04-07T00:00:00+00:00 [queued]>
[2020-04-07 22:47:55,174] {taskinstance.py:866} INFO - 
--------------------------------------------------------------------------------
[2020-04-07 22:47:55,174] {taskinstance.py:867} INFO - Starting attempt 1 of 2
[2020-04-07 22:47:55,174] {taskinstance.py:868} INFO - 
--------------------------------------------------------------------------------
[2020-04-07 22:47:55,182] {taskinstance.py:887} INFO - Executing <Task(PythonOperator): create_tbl_sample> on 2020-04-07T00:00:00+00:00
[2020-04-07 22:47:55,184] {standard_task_runner.py:53} INFO - Started process 74940 to run task
[2020-04-07 22:47:55,241] {logging_mixin.py:112} INFO - Running %s on host %s <TaskInstance: atp_data07.create_tbl_sample 2020-04-07T00:00:00+00:00 [running]> 1.0.0.0.0.0.0.0.0.0.0.0.0.0.0.0.0.0.0.0.0.0.0.0.0.0.0.0.0.0.0.0.ip6.arpa
[2020-04-07 22:47:55,270] {taskinstance.py:1128} ERROR - relation "sample" already exists
Traceback (most recent call last):
  File "/Users/cchavez/opt/anaconda3/envs/airflow/lib/python3.7/site-packages/airflow/models/taskinstance.py", line 966, in _run_raw_task
    result = task_copy.execute(context=context)
  File "/Users/cchavez/opt/anaconda3/envs/airflow/lib/python3.7/site-packages/airflow/operators/python_operator.py", line 113, in execute
    return_value = self.execute_callable()
  File "/Users/cchavez/opt/anaconda3/envs/airflow/lib/python3.7/site-packages/airflow/operators/python_operator.py", line 118, in execute_callable
    return self.python_callable(*self.op_args, **self.op_kwargs)
  File "/Users/cchavez/dev/airflow_home/dags/atp_data07.py", line 60, in create_tbl_sample
    """)
psycopg2.errors.DuplicateTable: relation "sample" already exists

[2020-04-07 22:47:55,275] {taskinstance.py:1151} INFO - Marking task as UP_FOR_RETRY
[2020-04-07 22:48:05,124] {logging_mixin.py:112} INFO - [2020-04-07 22:48:05,123] {local_task_job.py:103} INFO - Task exited with return code 1
[2020-04-07 23:32:15,286] {taskinstance.py:655} INFO - Dependencies all met for <TaskInstance: atp_data07.create_tbl_sample 2020-04-07T00:00:00+00:00 [queued]>
[2020-04-07 23:32:15,297] {taskinstance.py:655} INFO - Dependencies all met for <TaskInstance: atp_data07.create_tbl_sample 2020-04-07T00:00:00+00:00 [queued]>
[2020-04-07 23:32:15,297] {taskinstance.py:866} INFO - 
--------------------------------------------------------------------------------
[2020-04-07 23:32:15,297] {taskinstance.py:867} INFO - Starting attempt 1 of 1
[2020-04-07 23:32:15,297] {taskinstance.py:868} INFO - 
--------------------------------------------------------------------------------
[2020-04-07 23:32:15,303] {taskinstance.py:887} INFO - Executing <Task(PythonOperator): create_tbl_sample> on 2020-04-07T00:00:00+00:00
[2020-04-07 23:32:15,305] {standard_task_runner.py:53} INFO - Started process 76525 to run task
[2020-04-07 23:32:15,350] {logging_mixin.py:112} INFO - Running %s on host %s <TaskInstance: atp_data07.create_tbl_sample 2020-04-07T00:00:00+00:00 [running]> 1.0.0.0.0.0.0.0.0.0.0.0.0.0.0.0.0.0.0.0.0.0.0.0.0.0.0.0.0.0.0.0.ip6.arpa
[2020-04-07 23:32:15,368] {taskinstance.py:1128} ERROR - syntax error at or near "Id"
LINE 4:         Id varchar(255),
                ^
Traceback (most recent call last):
  File "/Users/cchavez/opt/anaconda3/envs/airflow/lib/python3.7/site-packages/airflow/models/taskinstance.py", line 966, in _run_raw_task
    result = task_copy.execute(context=context)
  File "/Users/cchavez/opt/anaconda3/envs/airflow/lib/python3.7/site-packages/airflow/operators/python_operator.py", line 113, in execute
    return_value = self.execute_callable()
  File "/Users/cchavez/opt/anaconda3/envs/airflow/lib/python3.7/site-packages/airflow/operators/python_operator.py", line 118, in execute_callable
    return self.python_callable(*self.op_args, **self.op_kwargs)
  File "/Users/cchavez/dev/airflow_home/dags/atp_data07.py", line 61, in create_tbl_sample
    """)
psycopg2.errors.SyntaxError: syntax error at or near "Id"
LINE 4:         Id varchar(255),
                ^

[2020-04-07 23:32:15,372] {taskinstance.py:1185} INFO - Marking task as FAILED.dag_id=atp_data07, task_id=create_tbl_sample, execution_date=20200407T000000, start_date=20200408T033215, end_date=20200408T033215
[2020-04-07 23:32:25,241] {logging_mixin.py:112} INFO - [2020-04-07 23:32:25,241] {local_task_job.py:103} INFO - Task exited with return code 1
[2020-04-08 00:11:04,628] {taskinstance.py:655} INFO - Dependencies all met for <TaskInstance: atp_data07.create_tbl_sample 2020-04-07T00:00:00+00:00 [queued]>
[2020-04-08 00:11:04,637] {taskinstance.py:655} INFO - Dependencies all met for <TaskInstance: atp_data07.create_tbl_sample 2020-04-07T00:00:00+00:00 [queued]>
[2020-04-08 00:11:04,638] {taskinstance.py:866} INFO - 
--------------------------------------------------------------------------------
[2020-04-08 00:11:04,638] {taskinstance.py:867} INFO - Starting attempt 1 of 1
[2020-04-08 00:11:04,638] {taskinstance.py:868} INFO - 
--------------------------------------------------------------------------------
[2020-04-08 00:11:04,643] {taskinstance.py:887} INFO - Executing <Task(PythonOperator): create_tbl_sample> on 2020-04-07T00:00:00+00:00
[2020-04-08 00:11:04,645] {standard_task_runner.py:53} INFO - Started process 78016 to run task
[2020-04-08 00:11:04,724] {logging_mixin.py:112} INFO - Running %s on host %s <TaskInstance: atp_data07.create_tbl_sample 2020-04-07T00:00:00+00:00 [running]> 1.0.0.0.0.0.0.0.0.0.0.0.0.0.0.0.0.0.0.0.0.0.0.0.0.0.0.0.0.0.0.0.ip6.arpa
[2020-04-08 00:11:04,752] {taskinstance.py:1128} ERROR - relation "sample" already exists
Traceback (most recent call last):
  File "/Users/cchavez/opt/anaconda3/envs/airflow/lib/python3.7/site-packages/airflow/models/taskinstance.py", line 966, in _run_raw_task
    result = task_copy.execute(context=context)
  File "/Users/cchavez/opt/anaconda3/envs/airflow/lib/python3.7/site-packages/airflow/operators/python_operator.py", line 113, in execute
    return_value = self.execute_callable()
  File "/Users/cchavez/opt/anaconda3/envs/airflow/lib/python3.7/site-packages/airflow/operators/python_operator.py", line 118, in execute_callable
    return self.python_callable(*self.op_args, **self.op_kwargs)
  File "/Users/cchavez/dev/airflow_home/dags/atp_data07.py", line 61, in create_tbl_sample
    """)
psycopg2.errors.DuplicateTable: relation "sample" already exists

[2020-04-08 00:11:04,754] {taskinstance.py:1185} INFO - Marking task as FAILED.dag_id=atp_data07, task_id=create_tbl_sample, execution_date=20200407T000000, start_date=20200408T041104, end_date=20200408T041104
[2020-04-08 00:11:14,594] {logging_mixin.py:112} INFO - [2020-04-08 00:11:14,592] {local_task_job.py:103} INFO - Task exited with return code 1
[2020-04-08 00:35:10,402] {taskinstance.py:655} INFO - Dependencies all met for <TaskInstance: atp_data07.create_tbl_sample 2020-04-07T00:00:00+00:00 [queued]>
[2020-04-08 00:35:10,411] {taskinstance.py:655} INFO - Dependencies all met for <TaskInstance: atp_data07.create_tbl_sample 2020-04-07T00:00:00+00:00 [queued]>
[2020-04-08 00:35:10,411] {taskinstance.py:866} INFO - 
--------------------------------------------------------------------------------
[2020-04-08 00:35:10,412] {taskinstance.py:867} INFO - Starting attempt 1 of 1
[2020-04-08 00:35:10,412] {taskinstance.py:868} INFO - 
--------------------------------------------------------------------------------
[2020-04-08 00:35:10,417] {taskinstance.py:887} INFO - Executing <Task(PythonOperator): create_tbl_sample> on 2020-04-07T00:00:00+00:00
[2020-04-08 00:35:10,419] {standard_task_runner.py:53} INFO - Started process 78867 to run task
[2020-04-08 00:35:10,464] {logging_mixin.py:112} INFO - Running %s on host %s <TaskInstance: atp_data07.create_tbl_sample 2020-04-07T00:00:00+00:00 [running]> 1.0.0.0.0.0.0.0.0.0.0.0.0.0.0.0.0.0.0.0.0.0.0.0.0.0.0.0.0.0.0.0.ip6.arpa
[2020-04-08 00:35:10,480] {taskinstance.py:1128} ERROR - syntax error at or near "CREATE"
LINE 3:         CREATE TABLE sample(
                ^
Traceback (most recent call last):
  File "/Users/cchavez/opt/anaconda3/envs/airflow/lib/python3.7/site-packages/airflow/models/taskinstance.py", line 966, in _run_raw_task
    result = task_copy.execute(context=context)
  File "/Users/cchavez/opt/anaconda3/envs/airflow/lib/python3.7/site-packages/airflow/operators/python_operator.py", line 113, in execute
    return_value = self.execute_callable()
  File "/Users/cchavez/opt/anaconda3/envs/airflow/lib/python3.7/site-packages/airflow/operators/python_operator.py", line 118, in execute_callable
    return self.python_callable(*self.op_args, **self.op_kwargs)
  File "/Users/cchavez/dev/airflow_home/dags/atp_data07.py", line 62, in create_tbl_sample
    """)
psycopg2.errors.SyntaxError: syntax error at or near "CREATE"
LINE 3:         CREATE TABLE sample(
                ^

[2020-04-08 00:35:10,482] {taskinstance.py:1185} INFO - Marking task as FAILED.dag_id=atp_data07, task_id=create_tbl_sample, execution_date=20200407T000000, start_date=20200408T043510, end_date=20200408T043510
[2020-04-08 00:35:20,359] {logging_mixin.py:112} INFO - [2020-04-08 00:35:20,358] {local_task_job.py:103} INFO - Task exited with return code 1
[2020-04-08 00:43:37,344] {taskinstance.py:655} INFO - Dependencies all met for <TaskInstance: atp_data07.create_tbl_sample 2020-04-07T00:00:00+00:00 [queued]>
[2020-04-08 00:43:37,353] {taskinstance.py:655} INFO - Dependencies all met for <TaskInstance: atp_data07.create_tbl_sample 2020-04-07T00:00:00+00:00 [queued]>
[2020-04-08 00:43:37,353] {taskinstance.py:866} INFO - 
--------------------------------------------------------------------------------
[2020-04-08 00:43:37,353] {taskinstance.py:867} INFO - Starting attempt 1 of 1
[2020-04-08 00:43:37,353] {taskinstance.py:868} INFO - 
--------------------------------------------------------------------------------
[2020-04-08 00:43:37,359] {taskinstance.py:887} INFO - Executing <Task(PythonOperator): create_tbl_sample> on 2020-04-07T00:00:00+00:00
[2020-04-08 00:43:37,361] {standard_task_runner.py:53} INFO - Started process 79163 to run task
[2020-04-08 00:43:37,411] {logging_mixin.py:112} INFO - Running %s on host %s <TaskInstance: atp_data07.create_tbl_sample 2020-04-07T00:00:00+00:00 [running]> 1.0.0.0.0.0.0.0.0.0.0.0.0.0.0.0.0.0.0.0.0.0.0.0.0.0.0.0.0.0.0.0.ip6.arpa
[2020-04-08 00:43:37,436] {taskinstance.py:1128} ERROR - syntax error at or near "CREATE"
LINE 3:         CREATE TABLE sample(
                ^
Traceback (most recent call last):
  File "/Users/cchavez/opt/anaconda3/envs/airflow/lib/python3.7/site-packages/airflow/models/taskinstance.py", line 966, in _run_raw_task
    result = task_copy.execute(context=context)
  File "/Users/cchavez/opt/anaconda3/envs/airflow/lib/python3.7/site-packages/airflow/operators/python_operator.py", line 113, in execute
    return_value = self.execute_callable()
  File "/Users/cchavez/opt/anaconda3/envs/airflow/lib/python3.7/site-packages/airflow/operators/python_operator.py", line 118, in execute_callable
    return self.python_callable(*self.op_args, **self.op_kwargs)
  File "/Users/cchavez/dev/airflow_home/dags/atp_data07.py", line 62, in create_tbl_sample
    """)
psycopg2.errors.SyntaxError: syntax error at or near "CREATE"
LINE 3:         CREATE TABLE sample(
                ^

[2020-04-08 00:43:37,440] {taskinstance.py:1185} INFO - Marking task as FAILED.dag_id=atp_data07, task_id=create_tbl_sample, execution_date=20200407T000000, start_date=20200408T044337, end_date=20200408T044337
[2020-04-08 00:43:47,304] {logging_mixin.py:112} INFO - [2020-04-08 00:43:47,303] {local_task_job.py:103} INFO - Task exited with return code 1
[2020-04-08 00:51:31,620] {taskinstance.py:655} INFO - Dependencies all met for <TaskInstance: atp_data07.create_tbl_sample 2020-04-07T00:00:00+00:00 [queued]>
[2020-04-08 00:51:31,629] {taskinstance.py:655} INFO - Dependencies all met for <TaskInstance: atp_data07.create_tbl_sample 2020-04-07T00:00:00+00:00 [queued]>
[2020-04-08 00:51:31,629] {taskinstance.py:866} INFO - 
--------------------------------------------------------------------------------
[2020-04-08 00:51:31,629] {taskinstance.py:867} INFO - Starting attempt 1 of 1
[2020-04-08 00:51:31,629] {taskinstance.py:868} INFO - 
--------------------------------------------------------------------------------
[2020-04-08 00:51:31,635] {taskinstance.py:887} INFO - Executing <Task(PythonOperator): create_tbl_sample> on 2020-04-07T00:00:00+00:00
[2020-04-08 00:51:31,637] {standard_task_runner.py:53} INFO - Started process 79462 to run task
[2020-04-08 00:51:31,686] {logging_mixin.py:112} INFO - Running %s on host %s <TaskInstance: atp_data07.create_tbl_sample 2020-04-07T00:00:00+00:00 [running]> zipcodes-MacBook-Pro-4.local
[2020-04-08 00:51:31,708] {taskinstance.py:1128} ERROR - syntax error at or near "CREATE"
LINE 3:         CREATE TABLE sample(
                ^
Traceback (most recent call last):
  File "/Users/cchavez/opt/anaconda3/envs/airflow/lib/python3.7/site-packages/airflow/models/taskinstance.py", line 966, in _run_raw_task
    result = task_copy.execute(context=context)
  File "/Users/cchavez/opt/anaconda3/envs/airflow/lib/python3.7/site-packages/airflow/operators/python_operator.py", line 113, in execute
    return_value = self.execute_callable()
  File "/Users/cchavez/opt/anaconda3/envs/airflow/lib/python3.7/site-packages/airflow/operators/python_operator.py", line 118, in execute_callable
    return self.python_callable(*self.op_args, **self.op_kwargs)
  File "/Users/cchavez/dev/airflow_home/dags/atp_data07.py", line 62, in create_tbl_sample
    """)
psycopg2.errors.SyntaxError: syntax error at or near "CREATE"
LINE 3:         CREATE TABLE sample(
                ^

[2020-04-08 00:51:31,711] {taskinstance.py:1185} INFO - Marking task as FAILED.dag_id=atp_data07, task_id=create_tbl_sample, execution_date=20200407T000000, start_date=20200408T045131, end_date=20200408T045131
[2020-04-08 00:51:41,581] {logging_mixin.py:112} INFO - [2020-04-08 00:51:41,580] {local_task_job.py:103} INFO - Task exited with return code 1
[2020-04-08 01:03:30,878] {taskinstance.py:655} INFO - Dependencies all met for <TaskInstance: atp_data07.create_tbl_sample 2020-04-07T00:00:00+00:00 [queued]>
[2020-04-08 01:03:30,886] {taskinstance.py:655} INFO - Dependencies all met for <TaskInstance: atp_data07.create_tbl_sample 2020-04-07T00:00:00+00:00 [queued]>
[2020-04-08 01:03:30,886] {taskinstance.py:866} INFO - 
--------------------------------------------------------------------------------
[2020-04-08 01:03:30,887] {taskinstance.py:867} INFO - Starting attempt 1 of 1
[2020-04-08 01:03:30,887] {taskinstance.py:868} INFO - 
--------------------------------------------------------------------------------
[2020-04-08 01:03:30,894] {taskinstance.py:887} INFO - Executing <Task(PythonOperator): create_tbl_sample> on 2020-04-07T00:00:00+00:00
[2020-04-08 01:03:30,896] {standard_task_runner.py:53} INFO - Started process 79881 to run task
[2020-04-08 01:03:30,946] {logging_mixin.py:112} INFO - Running %s on host %s <TaskInstance: atp_data07.create_tbl_sample 2020-04-07T00:00:00+00:00 [running]> 1.0.0.0.0.0.0.0.0.0.0.0.0.0.0.0.0.0.0.0.0.0.0.0.0.0.0.0.0.0.0.0.ip6.arpa
[2020-04-08 01:03:30,966] {taskinstance.py:1128} ERROR - syntax error at or near "CREATE"
LINE 3:         CREATE TABLE sample(
                ^
Traceback (most recent call last):
  File "/Users/cchavez/opt/anaconda3/envs/airflow/lib/python3.7/site-packages/airflow/models/taskinstance.py", line 966, in _run_raw_task
    result = task_copy.execute(context=context)
  File "/Users/cchavez/opt/anaconda3/envs/airflow/lib/python3.7/site-packages/airflow/operators/python_operator.py", line 113, in execute
    return_value = self.execute_callable()
  File "/Users/cchavez/opt/anaconda3/envs/airflow/lib/python3.7/site-packages/airflow/operators/python_operator.py", line 118, in execute_callable
    return self.python_callable(*self.op_args, **self.op_kwargs)
  File "/Users/cchavez/dev/airflow_home/dags/atp_data07.py", line 62, in create_tbl_sample
    """)
psycopg2.errors.SyntaxError: syntax error at or near "CREATE"
LINE 3:         CREATE TABLE sample(
                ^

[2020-04-08 01:03:30,969] {taskinstance.py:1185} INFO - Marking task as FAILED.dag_id=atp_data07, task_id=create_tbl_sample, execution_date=20200407T000000, start_date=20200408T050330, end_date=20200408T050330
[2020-04-08 01:03:40,840] {logging_mixin.py:112} INFO - [2020-04-08 01:03:40,840] {local_task_job.py:103} INFO - Task exited with return code 1
