[2020-04-07 22:54:09,035] {taskinstance.py:655} INFO - Dependencies all met for <TaskInstance: atp_data07.create_tbl_sample 2020-04-07T00:00:00+00:00 [queued]>
[2020-04-07 22:54:09,043] {taskinstance.py:655} INFO - Dependencies all met for <TaskInstance: atp_data07.create_tbl_sample 2020-04-07T00:00:00+00:00 [queued]>
[2020-04-07 22:54:09,044] {taskinstance.py:866} INFO - 
--------------------------------------------------------------------------------
[2020-04-07 22:54:09,044] {taskinstance.py:867} INFO - Starting attempt 2 of 2
[2020-04-07 22:54:09,044] {taskinstance.py:868} INFO - 
--------------------------------------------------------------------------------
[2020-04-07 22:54:09,051] {taskinstance.py:887} INFO - Executing <Task(PythonOperator): create_tbl_sample> on 2020-04-07T00:00:00+00:00
[2020-04-07 22:54:09,054] {standard_task_runner.py:53} INFO - Started process 75176 to run task
[2020-04-07 22:54:09,103] {logging_mixin.py:112} INFO - Running %s on host %s <TaskInstance: atp_data07.create_tbl_sample 2020-04-07T00:00:00+00:00 [running]> 1.0.0.0.0.0.0.0.0.0.0.0.0.0.0.0.0.0.0.0.0.0.0.0.0.0.0.0.0.0.0.0.ip6.arpa
[2020-04-07 22:54:09,128] {taskinstance.py:1128} ERROR - relation "sample" already exists
Traceback (most recent call last):
  File "/Users/cchavez/opt/anaconda3/envs/airflow/lib/python3.7/site-packages/airflow/models/taskinstance.py", line 966, in _run_raw_task
    result = task_copy.execute(context=context)
  File "/Users/cchavez/opt/anaconda3/envs/airflow/lib/python3.7/site-packages/airflow/operators/python_operator.py", line 113, in execute
    return_value = self.execute_callable()
  File "/Users/cchavez/opt/anaconda3/envs/airflow/lib/python3.7/site-packages/airflow/operators/python_operator.py", line 118, in execute_callable
    return self.python_callable(*self.op_args, **self.op_kwargs)
  File "/Users/cchavez/dev/airflow_home/dags/atp_data07.py", line 60, in create_tbl_sample
    """)
psycopg2.errors.DuplicateTable: relation "sample" already exists

[2020-04-07 22:54:09,133] {taskinstance.py:1170} INFO - All retries failed; marking task as FAILED.dag_id=atp_data07, task_id=create_tbl_sample, execution_date=20200407T000000, start_date=20200408T025409, end_date=20200408T025409
[2020-04-07 22:54:18,991] {logging_mixin.py:112} INFO - [2020-04-07 22:54:18,991] {local_task_job.py:103} INFO - Task exited with return code 1
