[2020-04-07 22:48:06,674] {taskinstance.py:655} INFO - Dependencies all met for <TaskInstance: atp_data07.insert_csv_sample 2020-04-06T00:00:00+00:00 [queued]>
[2020-04-07 22:48:06,683] {taskinstance.py:655} INFO - Dependencies all met for <TaskInstance: atp_data07.insert_csv_sample 2020-04-06T00:00:00+00:00 [queued]>
[2020-04-07 22:48:06,683] {taskinstance.py:866} INFO - 
--------------------------------------------------------------------------------
[2020-04-07 22:48:06,683] {taskinstance.py:867} INFO - Starting attempt 1 of 2
[2020-04-07 22:48:06,683] {taskinstance.py:868} INFO - 
--------------------------------------------------------------------------------
[2020-04-07 22:48:06,691] {taskinstance.py:887} INFO - Executing <Task(PythonOperator): insert_csv_sample> on 2020-04-06T00:00:00+00:00
[2020-04-07 22:48:06,693] {standard_task_runner.py:53} INFO - Started process 74946 to run task
[2020-04-07 22:48:06,745] {logging_mixin.py:112} INFO - Running %s on host %s <TaskInstance: atp_data07.insert_csv_sample 2020-04-06T00:00:00+00:00 [running]> 1.0.0.0.0.0.0.0.0.0.0.0.0.0.0.0.0.0.0.0.0.0.0.0.0.0.0.0.0.0.0.0.ip6.arpa
[2020-04-07 22:48:06,772] {taskinstance.py:1128} ERROR - extra data after last expected column
CONTEXT:  COPY sample, line 1: "0,1461,169277.0524984"
Traceback (most recent call last):
  File "/Users/cchavez/opt/anaconda3/envs/airflow/lib/python3.7/site-packages/airflow/models/taskinstance.py", line 966, in _run_raw_task
    result = task_copy.execute(context=context)
  File "/Users/cchavez/opt/anaconda3/envs/airflow/lib/python3.7/site-packages/airflow/operators/python_operator.py", line 113, in execute
    return_value = self.execute_callable()
  File "/Users/cchavez/opt/anaconda3/envs/airflow/lib/python3.7/site-packages/airflow/operators/python_operator.py", line 118, in execute_callable
    return self.python_callable(*self.op_args, **self.op_kwargs)
  File "/Users/cchavez/dev/airflow_home/dags/atp_data07.py", line 68, in insert_csv_sample
    cur.copy_from(f, 'sample', sep=',')
psycopg2.errors.BadCopyFileFormat: extra data after last expected column
CONTEXT:  COPY sample, line 1: "0,1461,169277.0524984"

[2020-04-07 22:48:06,775] {taskinstance.py:1151} INFO - Marking task as UP_FOR_RETRY
[2020-04-07 22:48:16,636] {logging_mixin.py:112} INFO - [2020-04-07 22:48:16,635] {local_task_job.py:103} INFO - Task exited with return code 1
[2020-04-08 00:54:01,596] {taskinstance.py:655} INFO - Dependencies all met for <TaskInstance: atp_data07.insert_csv_sample 2020-04-06T00:00:00+00:00 [queued]>
[2020-04-08 00:54:01,620] {taskinstance.py:655} INFO - Dependencies all met for <TaskInstance: atp_data07.insert_csv_sample 2020-04-06T00:00:00+00:00 [queued]>
[2020-04-08 00:54:01,620] {taskinstance.py:866} INFO - 
--------------------------------------------------------------------------------
[2020-04-08 00:54:01,621] {taskinstance.py:867} INFO - Starting attempt 1 of 1
[2020-04-08 00:54:01,621] {taskinstance.py:868} INFO - 
--------------------------------------------------------------------------------
[2020-04-08 00:54:01,629] {taskinstance.py:887} INFO - Executing <Task(PythonOperator): insert_csv_sample> on 2020-04-06T00:00:00+00:00
[2020-04-08 00:54:01,631] {standard_task_runner.py:53} INFO - Started process 79541 to run task
[2020-04-08 00:54:01,681] {logging_mixin.py:112} INFO - Running %s on host %s <TaskInstance: atp_data07.insert_csv_sample 2020-04-06T00:00:00+00:00 [running]> zipcodes-MacBook-Pro-4.local
[2020-04-08 00:54:01,719] {taskinstance.py:1128} ERROR - extra data after last expected column
CONTEXT:  COPY sample, line 1: "0,1461,169277.0524984"
Traceback (most recent call last):
  File "/Users/cchavez/opt/anaconda3/envs/airflow/lib/python3.7/site-packages/airflow/models/taskinstance.py", line 966, in _run_raw_task
    result = task_copy.execute(context=context)
  File "/Users/cchavez/opt/anaconda3/envs/airflow/lib/python3.7/site-packages/airflow/operators/python_operator.py", line 113, in execute
    return_value = self.execute_callable()
  File "/Users/cchavez/opt/anaconda3/envs/airflow/lib/python3.7/site-packages/airflow/operators/python_operator.py", line 118, in execute_callable
    return self.python_callable(*self.op_args, **self.op_kwargs)
  File "/Users/cchavez/dev/airflow_home/dags/atp_data07.py", line 70, in insert_csv_sample
    cur.copy_from(f, 'sample', sep=',')
psycopg2.errors.BadCopyFileFormat: extra data after last expected column
CONTEXT:  COPY sample, line 1: "0,1461,169277.0524984"

[2020-04-08 00:54:01,723] {taskinstance.py:1185} INFO - Marking task as FAILED.dag_id=atp_data07, task_id=insert_csv_sample, execution_date=20200406T000000, start_date=20200408T045401, end_date=20200408T045401
[2020-04-08 00:54:11,520] {logging_mixin.py:112} INFO - [2020-04-08 00:54:11,520] {local_task_job.py:103} INFO - Task exited with return code 1
[2020-04-08 02:33:09,150] {taskinstance.py:655} INFO - Dependencies all met for <TaskInstance: atp_data07.insert_csv_sample 2020-04-06T00:00:00+00:00 [queued]>
[2020-04-08 02:33:09,159] {taskinstance.py:655} INFO - Dependencies all met for <TaskInstance: atp_data07.insert_csv_sample 2020-04-06T00:00:00+00:00 [queued]>
[2020-04-08 02:33:09,160] {taskinstance.py:866} INFO - 
--------------------------------------------------------------------------------
[2020-04-08 02:33:09,160] {taskinstance.py:867} INFO - Starting attempt 1 of 1
[2020-04-08 02:33:09,160] {taskinstance.py:868} INFO - 
--------------------------------------------------------------------------------
[2020-04-08 02:33:09,165] {taskinstance.py:887} INFO - Executing <Task(PythonOperator): insert_csv_sample> on 2020-04-06T00:00:00+00:00
[2020-04-08 02:33:09,167] {standard_task_runner.py:53} INFO - Started process 81474 to run task
[2020-04-08 02:33:09,215] {logging_mixin.py:112} INFO - Running %s on host %s <TaskInstance: atp_data07.insert_csv_sample 2020-04-06T00:00:00+00:00 [running]> 1.0.0.0.0.0.0.0.0.0.0.0.0.0.0.0.0.0.0.0.0.0.0.0.0.0.0.0.0.0.0.0.ip6.arpa
[2020-04-08 02:33:09,246] {python_operator.py:114} INFO - Done. Returned value was: None
[2020-04-08 02:33:09,252] {taskinstance.py:1048} INFO - Marking task as SUCCESS.dag_id=atp_data07, task_id=insert_csv_sample, execution_date=20200406T000000, start_date=20200408T063309, end_date=20200408T063309
[2020-04-08 02:33:19,099] {logging_mixin.py:112} INFO - [2020-04-08 02:33:19,099] {local_task_job.py:103} INFO - Task exited with return code 0
