[2020-04-07 22:54:20,414] {taskinstance.py:655} INFO - Dependencies all met for <TaskInstance: atp_data07.insert_csv_sample 2020-04-06T00:00:00+00:00 [queued]>
[2020-04-07 22:54:20,423] {taskinstance.py:655} INFO - Dependencies all met for <TaskInstance: atp_data07.insert_csv_sample 2020-04-06T00:00:00+00:00 [queued]>
[2020-04-07 22:54:20,423] {taskinstance.py:866} INFO - 
--------------------------------------------------------------------------------
[2020-04-07 22:54:20,423] {taskinstance.py:867} INFO - Starting attempt 2 of 2
[2020-04-07 22:54:20,423] {taskinstance.py:868} INFO - 
--------------------------------------------------------------------------------
[2020-04-07 22:54:20,428] {taskinstance.py:887} INFO - Executing <Task(PythonOperator): insert_csv_sample> on 2020-04-06T00:00:00+00:00
[2020-04-07 22:54:20,430] {standard_task_runner.py:53} INFO - Started process 75182 to run task
[2020-04-07 22:54:20,476] {logging_mixin.py:112} INFO - Running %s on host %s <TaskInstance: atp_data07.insert_csv_sample 2020-04-06T00:00:00+00:00 [running]> 1.0.0.0.0.0.0.0.0.0.0.0.0.0.0.0.0.0.0.0.0.0.0.0.0.0.0.0.0.0.0.0.ip6.arpa
[2020-04-07 22:54:20,496] {taskinstance.py:1128} ERROR - extra data after last expected column
CONTEXT:  COPY sample, line 1: "0,1461,169277.0524984"
Traceback (most recent call last):
  File "/Users/cchavez/opt/anaconda3/envs/airflow/lib/python3.7/site-packages/airflow/models/taskinstance.py", line 966, in _run_raw_task
    result = task_copy.execute(context=context)
  File "/Users/cchavez/opt/anaconda3/envs/airflow/lib/python3.7/site-packages/airflow/operators/python_operator.py", line 113, in execute
    return_value = self.execute_callable()
  File "/Users/cchavez/opt/anaconda3/envs/airflow/lib/python3.7/site-packages/airflow/operators/python_operator.py", line 118, in execute_callable
    return self.python_callable(*self.op_args, **self.op_kwargs)
  File "/Users/cchavez/dev/airflow_home/dags/atp_data07.py", line 68, in insert_csv_sample
    cur.copy_from(f, 'sample', sep=',')
psycopg2.errors.BadCopyFileFormat: extra data after last expected column
CONTEXT:  COPY sample, line 1: "0,1461,169277.0524984"

[2020-04-07 22:54:20,498] {taskinstance.py:1170} INFO - All retries failed; marking task as FAILED.dag_id=atp_data07, task_id=insert_csv_sample, execution_date=20200406T000000, start_date=20200408T025420, end_date=20200408T025420
[2020-04-07 22:54:30,373] {logging_mixin.py:112} INFO - [2020-04-07 22:54:30,372] {local_task_job.py:103} INFO - Task exited with return code 1
