[2020-04-07 18:52:06,011] {taskinstance.py:655} INFO - Dependencies all met for <TaskInstance: atp_data07.unzip_api 2020-04-06T00:00:00+00:00 [queued]>
[2020-04-07 18:52:06,021] {taskinstance.py:655} INFO - Dependencies all met for <TaskInstance: atp_data07.unzip_api 2020-04-06T00:00:00+00:00 [queued]>
[2020-04-07 18:52:06,021] {taskinstance.py:866} INFO - 
--------------------------------------------------------------------------------
[2020-04-07 18:52:06,021] {taskinstance.py:867} INFO - Starting attempt 2 of 2
[2020-04-07 18:52:06,021] {taskinstance.py:868} INFO - 
--------------------------------------------------------------------------------
[2020-04-07 18:52:06,027] {taskinstance.py:887} INFO - Executing <Task(PythonOperator): unzip_api> on 2020-04-06T00:00:00+00:00
[2020-04-07 18:52:06,030] {standard_task_runner.py:53} INFO - Started process 67795 to run task
[2020-04-07 18:52:06,083] {logging_mixin.py:112} INFO - Running %s on host %s <TaskInstance: atp_data07.unzip_api 2020-04-06T00:00:00+00:00 [running]> 1.0.0.0.0.0.0.0.0.0.0.0.0.0.0.0.0.0.0.0.0.0.0.0.0.0.0.0.0.0.0.0.ip6.arpa
[2020-04-07 18:52:06,099] {taskinstance.py:1128} ERROR - "There is no item named 'Data.csv' in the archive"
Traceback (most recent call last):
  File "/Users/cchavez/opt/anaconda3/envs/airflow/lib/python3.7/site-packages/airflow/models/taskinstance.py", line 966, in _run_raw_task
    result = task_copy.execute(context=context)
  File "/Users/cchavez/opt/anaconda3/envs/airflow/lib/python3.7/site-packages/airflow/operators/python_operator.py", line 113, in execute
    return_value = self.execute_callable()
  File "/Users/cchavez/opt/anaconda3/envs/airflow/lib/python3.7/site-packages/airflow/operators/python_operator.py", line 118, in execute_callable
    return self.python_callable(*self.op_args, **self.op_kwargs)
  File "/Users/cchavez/dev/airflow_home/dags/atp_data07.py", line 44, in unzip
    df = pd.read_csv(zf.open('Data.csv'), encoding='ISO-8859-1')
  File "/Users/cchavez/opt/anaconda3/envs/airflow/lib/python3.7/zipfile.py", line 1503, in open
    zinfo = self.getinfo(name)
  File "/Users/cchavez/opt/anaconda3/envs/airflow/lib/python3.7/zipfile.py", line 1431, in getinfo
    'There is no item named %r in the archive' % name)
KeyError: "There is no item named 'Data.csv' in the archive"
[2020-04-07 18:52:06,103] {taskinstance.py:1170} INFO - All retries failed; marking task as FAILED.dag_id=atp_data07, task_id=unzip_api, execution_date=20200406T000000, start_date=20200407T225206, end_date=20200407T225206
[2020-04-07 18:52:15,976] {logging_mixin.py:112} INFO - [2020-04-07 18:52:15,975] {local_task_job.py:103} INFO - Task exited with return code 1
