[2020-04-07 15:49:34,101] {taskinstance.py:655} INFO - Dependencies all met for <TaskInstance: atp_data07.unzip_api 2020-04-05T00:00:00+00:00 [queued]>
[2020-04-07 15:49:34,109] {taskinstance.py:655} INFO - Dependencies all met for <TaskInstance: atp_data07.unzip_api 2020-04-05T00:00:00+00:00 [queued]>
[2020-04-07 15:49:34,109] {taskinstance.py:866} INFO - 
--------------------------------------------------------------------------------
[2020-04-07 15:49:34,109] {taskinstance.py:867} INFO - Starting attempt 1 of 2
[2020-04-07 15:49:34,109] {taskinstance.py:868} INFO - 
--------------------------------------------------------------------------------
[2020-04-07 15:49:34,115] {taskinstance.py:887} INFO - Executing <Task(PythonOperator): unzip_api> on 2020-04-05T00:00:00+00:00
[2020-04-07 15:49:34,117] {standard_task_runner.py:53} INFO - Started process 62855 to run task
[2020-04-07 15:49:34,164] {logging_mixin.py:112} INFO - Running %s on host %s <TaskInstance: atp_data07.unzip_api 2020-04-05T00:00:00+00:00 [running]> 1.0.0.0.0.0.0.0.0.0.0.0.0.0.0.0.0.0.0.0.0.0.0.0.0.0.0.0.0.0.0.0.ip6.arpa
[2020-04-07 15:49:34,181] {taskinstance.py:1128} ERROR - "There is no item named 'Data.csv' in the archive"
Traceback (most recent call last):
  File "/Users/cchavez/opt/anaconda3/envs/airflow/lib/python3.7/site-packages/airflow/models/taskinstance.py", line 966, in _run_raw_task
    result = task_copy.execute(context=context)
  File "/Users/cchavez/opt/anaconda3/envs/airflow/lib/python3.7/site-packages/airflow/operators/python_operator.py", line 113, in execute
    return_value = self.execute_callable()
  File "/Users/cchavez/opt/anaconda3/envs/airflow/lib/python3.7/site-packages/airflow/operators/python_operator.py", line 118, in execute_callable
    return self.python_callable(*self.op_args, **self.op_kwargs)
  File "/Users/cchavez/dev/airflow_home/dags/atp_data07.py", line 44, in unzip
    df = pd.read_csv(zf.open('Data.csv'), encoding='ISO-8859-1')
  File "/Users/cchavez/opt/anaconda3/envs/airflow/lib/python3.7/zipfile.py", line 1503, in open
    zinfo = self.getinfo(name)
  File "/Users/cchavez/opt/anaconda3/envs/airflow/lib/python3.7/zipfile.py", line 1431, in getinfo
    'There is no item named %r in the archive' % name)
KeyError: "There is no item named 'Data.csv' in the archive"
[2020-04-07 15:49:34,189] {taskinstance.py:1151} INFO - Marking task as UP_FOR_RETRY
[2020-04-07 15:49:44,067] {logging_mixin.py:112} INFO - [2020-04-07 15:49:44,066] {local_task_job.py:103} INFO - Task exited with return code 1
[2020-04-07 18:44:32,014] {taskinstance.py:655} INFO - Dependencies all met for <TaskInstance: atp_data07.unzip_api 2020-04-05T00:00:00+00:00 [queued]>
[2020-04-07 18:44:32,026] {taskinstance.py:655} INFO - Dependencies all met for <TaskInstance: atp_data07.unzip_api 2020-04-05T00:00:00+00:00 [queued]>
[2020-04-07 18:44:32,026] {taskinstance.py:866} INFO - 
--------------------------------------------------------------------------------
[2020-04-07 18:44:32,026] {taskinstance.py:867} INFO - Starting attempt 1 of 2
[2020-04-07 18:44:32,026] {taskinstance.py:868} INFO - 
--------------------------------------------------------------------------------
[2020-04-07 18:44:32,032] {taskinstance.py:887} INFO - Executing <Task(PythonOperator): unzip_api> on 2020-04-05T00:00:00+00:00
[2020-04-07 18:44:32,035] {standard_task_runner.py:53} INFO - Started process 65895 to run task
[2020-04-07 18:44:32,108] {logging_mixin.py:112} INFO - Running %s on host %s <TaskInstance: atp_data07.unzip_api 2020-04-05T00:00:00+00:00 [running]> 1.0.0.0.0.0.0.0.0.0.0.0.0.0.0.0.0.0.0.0.0.0.0.0.0.0.0.0.0.0.0.0.ip6.arpa
[2020-04-07 18:44:32,126] {taskinstance.py:1128} ERROR - "There is no item named 'Data.csv' in the archive"
Traceback (most recent call last):
  File "/Users/cchavez/opt/anaconda3/envs/airflow/lib/python3.7/site-packages/airflow/models/taskinstance.py", line 966, in _run_raw_task
    result = task_copy.execute(context=context)
  File "/Users/cchavez/opt/anaconda3/envs/airflow/lib/python3.7/site-packages/airflow/operators/python_operator.py", line 113, in execute
    return_value = self.execute_callable()
  File "/Users/cchavez/opt/anaconda3/envs/airflow/lib/python3.7/site-packages/airflow/operators/python_operator.py", line 118, in execute_callable
    return self.python_callable(*self.op_args, **self.op_kwargs)
  File "/Users/cchavez/dev/airflow_home/dags/atp_data07.py", line 44, in unzip
    df = pd.read_csv(zf.open('Data.csv'), encoding='ISO-8859-1')
  File "/Users/cchavez/opt/anaconda3/envs/airflow/lib/python3.7/zipfile.py", line 1503, in open
    zinfo = self.getinfo(name)
  File "/Users/cchavez/opt/anaconda3/envs/airflow/lib/python3.7/zipfile.py", line 1431, in getinfo
    'There is no item named %r in the archive' % name)
KeyError: "There is no item named 'Data.csv' in the archive"
[2020-04-07 18:44:32,131] {taskinstance.py:1151} INFO - Marking task as UP_FOR_RETRY
[2020-04-07 18:44:41,968] {logging_mixin.py:112} INFO - [2020-04-07 18:44:41,968] {local_task_job.py:103} INFO - Task exited with return code 1
