[2020-04-05 10:37:43,151] {taskinstance.py:655} INFO - Dependencies all met for <TaskInstance: stack_overflow_questions.create_table 2020-04-01T00:00:00+00:00 [queued]>
[2020-04-05 10:37:43,157] {taskinstance.py:655} INFO - Dependencies all met for <TaskInstance: stack_overflow_questions.create_table 2020-04-01T00:00:00+00:00 [queued]>
[2020-04-05 10:37:43,158] {taskinstance.py:866} INFO - 
--------------------------------------------------------------------------------
[2020-04-05 10:37:43,158] {taskinstance.py:867} INFO - Starting attempt 1 of 1
[2020-04-05 10:37:43,158] {taskinstance.py:868} INFO - 
--------------------------------------------------------------------------------
[2020-04-05 10:37:43,165] {taskinstance.py:887} INFO - Executing <Task(PostgresOperator): create_table> on 2020-04-01T00:00:00+00:00
[2020-04-05 10:37:43,167] {standard_task_runner.py:53} INFO - Started process 470 to run task
[2020-04-05 10:37:43,213] {logging_mixin.py:112} INFO - Running %s on host %s <TaskInstance: stack_overflow_questions.create_table 2020-04-01T00:00:00+00:00 [running]> 1.0.0.0.0.0.0.0.0.0.0.0.0.0.0.0.0.0.0.0.0.0.0.0.0.0.0.0.0.0.0.0.ip6.arpa
[2020-04-05 10:37:43,228] {postgres_operator.py:62} INFO - Executing: 
        DROP TABLE IF EXISTS public.questions;
        CREATE TABLE public.questions
        (
        title text,
        is_answered boolean,
        link character varying,
        score integer,
        tags text[],
        question_id integer NOT NULL,
        owner_reputation integer
        )
        
[2020-04-05 10:37:43,232] {logging_mixin.py:112} INFO - [2020-04-05 10:37:43,231] {base_hook.py:84} INFO - Using connection to: id: postgres_connection. Host: localhost, Port: 5432, Schema: stack_overflow, Login: postgres, Password: XXXXXXXX, extra: None
[2020-04-05 10:37:43,252] {taskinstance.py:1128} ERROR - FATAL:  database "stack_overflow" does not exist
Traceback (most recent call last):
  File "/Users/cchavez/opt/anaconda3/envs/airflow/lib/python3.7/site-packages/airflow/models/taskinstance.py", line 966, in _run_raw_task
    result = task_copy.execute(context=context)
  File "/Users/cchavez/opt/anaconda3/envs/airflow/lib/python3.7/site-packages/airflow/operators/postgres_operator.py", line 65, in execute
    self.hook.run(self.sql, self.autocommit, parameters=self.parameters)
  File "/Users/cchavez/opt/anaconda3/envs/airflow/lib/python3.7/site-packages/airflow/hooks/dbapi_hook.py", line 162, in run
    with closing(self.get_conn()) as conn:
  File "/Users/cchavez/opt/anaconda3/envs/airflow/lib/python3.7/site-packages/airflow/hooks/postgres_hook.py", line 93, in get_conn
    self.conn = psycopg2.connect(**conn_args)
  File "/Users/cchavez/opt/anaconda3/envs/airflow/lib/python3.7/site-packages/psycopg2/__init__.py", line 126, in connect
    conn = _connect(dsn, connection_factory=connection_factory, **kwasync)
psycopg2.OperationalError: FATAL:  database "stack_overflow" does not exist

[2020-04-05 10:37:43,271] {taskinstance.py:1185} INFO - Marking task as FAILED.dag_id=stack_overflow_questions, task_id=create_table, execution_date=20200401T000000, start_date=20200405T143743, end_date=20200405T143743
[2020-04-05 10:37:53,147] {logging_mixin.py:112} INFO - [2020-04-05 10:37:53,147] {local_task_job.py:103} INFO - Task exited with return code 1
